<?xml version="1.0" ?>
<!-- Generated using onshape-to-robot -->
<!-- Onshape https://cad.onshape.com/documents/804927696f06d877f3f1803e/w/3df6f6a8dcea50fb5658e3c0/e/e9ad89ea0c0270c6f03a5522 -->
<robot name="microduck">
  <!-- Link trunk_base -->
  <link name="trunk_base">
    <inertial>
      <origin xyz="-0.0158538 -0.000207016 0.0229615" rpy="0 0 0"/>
      <mass value="0.341837"/>
      <inertia ixx="0.000409441" ixy="-4.70504e-07" ixz="-4.69025e-05" iyy="0.000482274" iyz="1.00855e-06" izz="0.000321872"/>
    </inertial>
    <!-- Part electronics_hub -->
    <visual>
      <origin xyz="0.0125202 0 0.0352" rpy="-0 0 0"/>
      <geometry>
        <mesh filename="package://assets/electronics_hub.stl"/>
      </geometry>
      <material name="electronics_hub_material">
        <color rgba="0.615686 0.811765 0.929412 1"/>
      </material>
    </visual>
    <collision>
      <origin xyz="0.0125202 0 0.0352" rpy="-0 0 0"/>
      <geometry>
        <mesh filename="package://assets/electronics_hub.stl"/>
      </geometry>
    </collision>
    <!-- Part elec_rpi_robot_hat_pcb -->
    <visual>
      <origin xyz="-0.0115748 0.029005 0.06442" rpy="0 -0 -1.5708"/>
      <geometry>
        <mesh filename="package://assets/elec_rpi_robot_hat_pcb.stl"/>
      </geometry>
      <material name="elec_rpi_robot_hat_pcb_material">
        <color rgba="0.313725 0.486275 0.411765 1"/>
      </material>
    </visual>
    <collision>
      <origin xyz="-0.0115748 0.029005 0.06442" rpy="0 -0 -1.5708"/>
      <geometry>
        <mesh filename="package://assets/elec_rpi_robot_hat_pcb.stl"/>
      </geometry>
    </collision>
    <!-- Part xl330 -->
    <visual>
      <origin xyz="0.0125202 -0.02 0.0353" rpy="3.14159 -1.5708 0"/>
      <geometry>
        <mesh filename="package://assets/xl330.stl"/>
      </geometry>
      <material name="xl330_material">
        <color rgba="0.286275 0.286275 0.286275 1"/>
      </material>
    </visual>
    <collision>
      <origin xyz="0.0125202 -0.02 0.0353" rpy="3.14159 -1.5708 0"/>
      <geometry>
        <mesh filename="package://assets/xl330.stl"/>
      </geometry>
    </collision>
    <!-- Part bottom_shell -->
    <visual>
      <origin xyz="0.0125202 -0.00095 0.0352" rpy="-0 0 0"/>
      <geometry>
        <mesh filename="package://assets/bottom_shell.stl"/>
      </geometry>
      <material name="bottom_shell_material">
        <color rgba="0.6 0.6 0.6 1"/>
      </material>
    </visual>
    <collision>
      <origin xyz="0.0125202 -0.00095 0.0352" rpy="-0 0 0"/>
      <geometry>
        <mesh filename="package://assets/bottom_shell.stl"/>
      </geometry>
    </collision>
    <!-- Part bearing -->
    <visual>
      <origin xyz="0.0125202 -0.04 0.0352" rpy="-0 0 0"/>
      <geometry>
        <mesh filename="package://assets/bearing.stl"/>
      </geometry>
      <material name="bearing_material">
        <color rgba="0.701961 0.701961 0.701961 1"/>
      </material>
    </visual>
    <collision>
      <origin xyz="0.0125202 -0.04 0.0352" rpy="-0 0 0"/>
      <geometry>
        <mesh filename="package://assets/bearing.stl"/>
      </geometry>
    </collision>
    <!-- Part trunk_yaw -->
    <visual>
      <origin xyz="0.0125202 0 0.0352" rpy="-0 0 0"/>
      <geometry>
        <mesh filename="package://assets/trunk_yaw.stl"/>
      </geometry>
      <material name="trunk_yaw_material">
        <color rgba="0.235294 0.235294 0.235294 1"/>
      </material>
    </visual>
    <collision>
      <origin xyz="0.0125202 0 0.0352" rpy="-0 0 0"/>
      <geometry>
        <mesh filename="package://assets/trunk_yaw.stl"/>
      </geometry>
    </collision>
    <!-- Part top_shell -->
    <visual>
      <origin xyz="0.0124202 -0.00095 0.0352" rpy="-0 0 0"/>
      <geometry>
        <mesh filename="package://assets/top_shell.stl"/>
      </geometry>
      <material name="top_shell_material">
        <color rgba="0.6 0.6 0.6 1"/>
      </material>
    </visual>
    <collision>
      <origin xyz="0.0124202 -0.00095 0.0352" rpy="-0 0 0"/>
      <geometry>
        <mesh filename="package://assets/top_shell.stl"/>
      </geometry>
    </collision>
    <!-- Part xl330_2 -->
    <visual>
      <origin xyz="0.0125202 0.02 0.0353" rpy="3.14159 -1.5708 0"/>
      <geometry>
        <mesh filename="package://assets/xl330.stl"/>
      </geometry>
      <material name="xl330_2_material">
        <color rgba="0.286275 0.286275 0.286275 1"/>
      </material>
    </visual>
    <collision>
      <origin xyz="0.0125202 0.02 0.0353" rpy="3.14159 -1.5708 0"/>
      <geometry>
        <mesh filename="package://assets/xl330.stl"/>
      </geometry>
    </collision>
    <!-- Part std00333_plast_tcb_torx_2_5x8__configuration_copy_of_default -->
    <visual>
      <origin xyz="-0.0241298 -0.0244 -0.0172" rpy="-0 0 0"/>
      <geometry>
        <mesh filename="package://assets/std00333_plast_tcb_torx_2_5x8__configuration_copy_of_default.stl"/>
      </geometry>
      <material name="std00333_plast_tcb_torx_2_5x8__configuration_copy_of_default_material">
        <color rgba="0.901961 0.901961 0.901961 1"/>
      </material>
    </visual>
    <collision>
      <origin xyz="-0.0241298 -0.0244 -0.0172" rpy="-0 0 0"/>
      <geometry>
        <mesh filename="package://assets/std00333_plast_tcb_torx_2_5x8__configuration_copy_of_default.stl"/>
      </geometry>
    </collision>
    <!-- Part pcb__raspberry_pi_zero_2_w -->
    <visual>
      <origin xyz="-0.0230798 0 0.05629" rpy="-1.5708 0 1.5708"/>
      <geometry>
        <mesh filename="package://assets/pcb__raspberry_pi_zero_2_w.stl"/>
      </geometry>
      <material name="pcb__raspberry_pi_zero_2_w_material">
        <color rgba="0.498039 0.498039 0.498039 1"/>
      </material>
    </visual>
    <collision>
      <origin xyz="-0.0230798 0 0.05629" rpy="-1.5708 0 1.5708"/>
      <geometry>
        <mesh filename="package://assets/pcb__raspberry_pi_zero_2_w.stl"/>
      </geometry>
    </collision>
    <!-- Part xl330_3 -->
    <visual>
      <origin xyz="0.0375202 0.0001 0.0552" rpy="0 -0 1.5708"/>
      <geometry>
        <mesh filename="package://assets/xl330.stl"/>
      </geometry>
      <material name="xl330_3_material">
        <color rgba="0.286275 0.286275 0.286275 1"/>
      </material>
    </visual>
    <collision>
      <origin xyz="0.0375202 0.0001 0.0552" rpy="0 -0 1.5708"/>
      <geometry>
        <mesh filename="package://assets/xl330.stl"/>
      </geometry>
    </collision>
    <!-- Part battery_tighten -->
    <visual>
      <origin xyz="0.0125202 0 0.0372" rpy="-0 0 0"/>
      <geometry>
        <mesh filename="package://assets/battery_tighten.stl"/>
      </geometry>
      <material name="battery_tighten_material">
        <color rgba="0.917647 0.917647 0.917647 1"/>
      </material>
    </visual>
    <collision>
      <origin xyz="0.0125202 0 0.0372" rpy="-0 0 0"/>
      <geometry>
        <mesh filename="package://assets/battery_tighten.stl"/>
      </geometry>
    </collision>
    <!-- Part std00333_plast_tcb_torx_2_5x8__configuration_copy_of_default_2 -->
    <visual>
      <origin xyz="-0.0241298 0.0244 -0.0172" rpy="-0 0 0"/>
      <geometry>
        <mesh filename="package://assets/std00333_plast_tcb_torx_2_5x8__configuration_copy_of_default.stl"/>
      </geometry>
      <material name="std00333_plast_tcb_torx_2_5x8__configuration_copy_of_default_2_material">
        <color rgba="0.901961 0.901961 0.901961 1"/>
      </material>
    </visual>
    <collision>
      <origin xyz="-0.0241298 0.0244 -0.0172" rpy="-0 0 0"/>
      <geometry>
        <mesh filename="package://assets/std00333_plast_tcb_torx_2_5x8__configuration_copy_of_default.stl"/>
      </geometry>
    </collision>
    <!-- Part bearing_2 -->
    <visual>
      <origin xyz="0.0125202 -0 0.0352" rpy="-0 -0 0"/>
      <geometry>
        <mesh filename="package://assets/bearing.stl"/>
      </geometry>
      <material name="bearing_2_material">
        <color rgba="0.701961 0.701961 0.701961 1"/>
      </material>
    </visual>
    <collision>
      <origin xyz="0.0125202 -0 0.0352" rpy="-0 -0 0"/>
      <geometry>
        <mesh filename="package://assets/bearing.stl"/>
      </geometry>
    </collision>
    <!-- Part np_f970 -->
    <visual>
      <origin xyz="-0.0337298 0 0.00875" rpy="3.14159 -0 -1.5708"/>
      <geometry>
        <mesh filename="package://assets/np_f970.stl"/>
      </geometry>
      <material name="np_f970_material">
        <color rgba="0.301961 0.301961 0.301961 1"/>
      </material>
    </visual>
    <collision>
      <origin xyz="-0.0337298 0 0.00875" rpy="3.14159 -0 -1.5708"/>
      <geometry>
        <mesh filename="package://assets/np_f970.stl"/>
      </geometry>
    </collision>
    <!-- Part trunk_base -->
    <visual>
      <origin xyz="0.0125202 0 0.0352" rpy="-0 0 0"/>
      <geometry>
        <mesh filename="package://assets/trunk_base.stl"/>
      </geometry>
      <material name="trunk_base_material">
        <color rgba="0.235294 0.235294 0.235294 1"/>
      </material>
    </visual>
    <collision>
      <origin xyz="0.0125202 0 0.0352" rpy="-0 0 0"/>
      <geometry>
        <mesh filename="package://assets/trunk_base.stl"/>
      </geometry>
    </collision>
    <!-- Part np_f550_holder -->
    <visual>
      <origin xyz="0.0125202 0 0.0352" rpy="-0 0 0"/>
      <geometry>
        <mesh filename="package://assets/np_f550_holder.stl"/>
      </geometry>
      <material name="np_f550_holder_material">
        <color rgba="0.231373 0.380392 0.705882 1"/>
      </material>
    </visual>
    <collision>
      <origin xyz="0.0125202 0 0.0352" rpy="-0 0 0"/>
      <geometry>
        <mesh filename="package://assets/np_f550_holder.stl"/>
      </geometry>
    </collision>
  </link>
  <!-- Frame imu (dummy link + fixed joint) -->
  <link name="imu">
    <origin xyz="0 0 0" rpy="0 -0 0"/>
    <inertial>
      <origin xyz="0 0 0" rpy="0 0 0"/>
      <mass value="1e-9"/>
      <inertia ixx="0" ixy="0" ixz="0" iyy="0" iyz="0" izz="0"/>
    </inertial>
  </link>
  <joint name="imu_frame" type="fixed">
    <origin xyz="-0.0162825 0.00812245 0.06526" rpy="0 -0 -0"/>
    <parent link="trunk_base"/>
    <child link="imu"/>
    <axis xyz="0 0 0"/>
  </joint>
  <!-- Frame torso_camera (dummy link + fixed joint) -->
  <link name="torso_camera">
    <origin xyz="0 0 0" rpy="0 -0 0"/>
    <inertial>
      <origin xyz="0 0 0" rpy="0 0 0"/>
      <mass value="1e-9"/>
      <inertia ixx="0" ixy="0" ixz="0" iyy="0" iyz="0" izz="0"/>
    </inertial>
  </link>
  <joint name="torso_camera_frame" type="fixed">
    <origin xyz="0.0506202 -0 0.0305024" rpy="-0 -0 -0"/>
    <parent link="trunk_base"/>
    <child link="torso_camera"/>
    <axis xyz="0 0 0"/>
  </joint>
  <!-- Link roll_motor_bottom -->
  <link name="roll_motor_bottom">
    <inertial>
      <origin xyz="0 -0.000243808 0.0205921" rpy="0 0 0"/>
      <mass value="0.0250187"/>
      <inertia ixx="5.56855e-06" ixy="0" ixz="-0" iyy="5.01807e-06" iyz="-1.8994e-08" izz="2.44472e-06"/>
    </inertial>
    <!-- Part roll_motor_bottom -->
    <visual>
      <origin xyz="0.02 -5e-05 -0.0146" rpy="3.14159 -0 -1.5708"/>
      <geometry>
        <mesh filename="package://assets/roll_motor_bottom.stl"/>
      </geometry>
      <material name="roll_motor_bottom_material">
        <color rgba="0.235294 0.235294 0.235294 1"/>
      </material>
    </visual>
    <collision>
      <origin xyz="0.02 -5e-05 -0.0146" rpy="3.14159 -0 -1.5708"/>
      <geometry>
        <mesh filename="package://assets/roll_motor_bottom.stl"/>
      </geometry>
    </collision>
    <!-- Part roll_motor_top -->
    <visual>
      <origin xyz="0.02 0 -0.0146" rpy="3.14159 -0 -1.5708"/>
      <geometry>
        <mesh filename="package://assets/roll_motor_top.stl"/>
      </geometry>
      <material name="roll_motor_top_material">
        <color rgba="0.235294 0.235294 0.235294 1"/>
      </material>
    </visual>
    <collision>
      <origin xyz="0.02 0 -0.0146" rpy="3.14159 -0 -1.5708"/>
      <geometry>
        <mesh filename="package://assets/roll_motor_top.stl"/>
      </geometry>
    </collision>
    <!-- Part xl330_4 -->
    <visual>
      <origin xyz="0 -5e-05 0.0286" rpy="0 0 1.5708"/>
      <geometry>
        <mesh filename="package://assets/xl330.stl"/>
      </geometry>
      <material name="xl330_4_material">
        <color rgba="0.286275 0.286275 0.286275 1"/>
      </material>
    </visual>
    <collision>
      <origin xyz="0 -5e-05 0.0286" rpy="0 0 1.5708"/>
      <geometry>
        <mesh filename="package://assets/xl330.stl"/>
      </geometry>
    </collision>
  </link>
  <!-- Link left_roll_to_pitch -->
  <link name="left_roll_to_pitch">
    <inertial>
      <origin xyz="0.0359029 0.00016252 -0.0142127" rpy="0 0 0"/>
      <mass value="0.02709"/>
      <inertia ixx="4.61259e-06" ixy="7.4483e-08" ixz="4.8292e-08" iyy="7.88911e-06" iyz="1.1887e-08" izz="5.4019e-06"/>
    </inertial>
    <!-- Part left_roll_to_pitch -->
    <visual>
      <origin xyz="-0.02 0.0432 -0.0145" rpy="-1.5708 -1.5708 0"/>
      <geometry>
        <mesh filename="package://assets/left_roll_to_pitch.stl"/>
      </geometry>
      <material name="left_roll_to_pitch_material">
        <color rgba="0.235294 0.235294 0.235294 1"/>
      </material>
    </visual>
    <collision>
      <origin xyz="-0.02 0.0432 -0.0145" rpy="-1.5708 -1.5708 0"/>
      <geometry>
        <mesh filename="package://assets/left_roll_to_pitch.stl"/>
      </geometry>
    </collision>
    <!-- Part xl330_5 -->
    <visual>
      <origin xyz="0.0399 -0 -0.0245" rpy="3.14159 0 3.14159"/>
      <geometry>
        <mesh filename="package://assets/xl330.stl"/>
      </geometry>
      <material name="xl330_5_material">
        <color rgba="0.286275 0.286275 0.286275 1"/>
      </material>
    </visual>
    <collision>
      <origin xyz="0.0399 -0 -0.0245" rpy="3.14159 0 3.14159"/>
      <geometry>
        <mesh filename="package://assets/xl330.stl"/>
      </geometry>
    </collision>
  </link>
  <!-- Link leg_plate -->
  <link name="leg_plate">
    <inertial>
      <origin xyz="-0.0244608 -0.0171277 -0.0142503" rpy="0 0 0"/>
      <mass value="0.0242215"/>
      <inertia ixx="4.17502e-06" ixy="-1.46283e-06" ixz="1.7015e-08" iyy="5.23987e-06" iyz="1.1914e-08" izz="5.11862e-06"/>
    </inertial>
    <!-- Part spacer -->
    <visual>
      <origin xyz="0.0415246 0.0160136 -0.0747" rpy="1.5708 0 2.18166"/>
      <geometry>
        <mesh filename="package://assets/spacer.stl"/>
      </geometry>
      <material name="spacer_material">
        <color rgba="0.6 0.6 0.6 1"/>
      </material>
    </visual>
    <collision>
      <origin xyz="0.0415246 0.0160136 -0.0747" rpy="1.5708 0 2.18166"/>
      <geometry>
        <mesh filename="package://assets/spacer.stl"/>
      </geometry>
    </collision>
    <!-- Part leg_plate -->
    <visual>
      <origin xyz="0.0411231 0.016587 0.0455" rpy="-1.5708 -0 -0.959931"/>
      <geometry>
        <mesh filename="package://assets/leg_plate.stl"/>
      </geometry>
      <material name="leg_plate_material">
        <color rgba="0.235294 0.235294 0.235294 1"/>
      </material>
    </visual>
    <collision>
      <origin xyz="0.0411231 0.016587 0.0455" rpy="-1.5708 -0 -0.959931"/>
      <geometry>
        <mesh filename="package://assets/leg_plate.stl"/>
      </geometry>
    </collision>
    <!-- Part leg_plate_2 -->
    <visual>
      <origin xyz="0.0296516 0.03297 -0.0745" rpy="1.5708 0 2.18166"/>
      <geometry>
        <mesh filename="package://assets/leg_plate.stl"/>
      </geometry>
      <material name="leg_plate_2_material">
        <color rgba="0.235294 0.235294 0.235294 1"/>
      </material>
    </visual>
    <collision>
      <origin xyz="0.0296516 0.03297 -0.0745" rpy="1.5708 0 2.18166"/>
      <geometry>
        <mesh filename="package://assets/leg_plate.stl"/>
      </geometry>
    </collision>
    <!-- Part spacer_2 -->
    <visual>
      <origin xyz="0.0296516 0.03297 -0.0747" rpy="1.5708 0 2.18166"/>
      <geometry>
        <mesh filename="package://assets/spacer.stl"/>
      </geometry>
      <material name="spacer_2_material">
        <color rgba="0.6 0.6 0.6 1"/>
      </material>
    </visual>
    <collision>
      <origin xyz="0.0296516 0.03297 -0.0747" rpy="1.5708 0 2.18166"/>
      <geometry>
        <mesh filename="package://assets/spacer.stl"/>
      </geometry>
    </collision>
    <!-- Part xl330_6 -->
    <visual>
      <origin xyz="-0.0344044 -0.0240902 -0.0145" rpy="2.53073 1.5708 0"/>
      <geometry>
        <mesh filename="package://assets/xl330.stl"/>
      </geometry>
      <material name="xl330_6_material">
        <color rgba="0.286275 0.286275 0.286275 1"/>
      </material>
    </visual>
    <collision>
      <origin xyz="-0.0344044 -0.0240902 -0.0145" rpy="2.53073 1.5708 0"/>
      <geometry>
        <mesh filename="package://assets/xl330.stl"/>
      </geometry>
    </collision>
  </link>
  <!-- Link leg_plate_2 -->
  <link name="leg_plate_2">
    <inertial>
      <origin xyz="-0.0286609 -0.0104317 -0.0142358" rpy="0 0 0"/>
      <mass value="0.02326"/>
      <inertia ixx="3.36548e-06" ixy="-9.56811e-07" ixz="1.4432e-08" iyy="5.64605e-06" iyz="5.253e-09" izz="4.77213e-06"/>
    </inertial>
    <!-- Part leg_plate_3 -->
    <visual>
      <origin xyz="0.0371745 0.0241722 -0.0745" rpy="1.5708 0 1.91986"/>
      <geometry>
        <mesh filename="package://assets/leg_plate.stl"/>
      </geometry>
      <material name="leg_plate_3_material">
        <color rgba="0.235294 0.235294 0.235294 1"/>
      </material>
    </visual>
    <collision>
      <origin xyz="0.0371745 0.0241722 -0.0745" rpy="1.5708 0 1.91986"/>
      <geometry>
        <mesh filename="package://assets/leg_plate.stl"/>
      </geometry>
    </collision>
    <!-- Part leg_plate_4 -->
    <visual>
      <origin xyz="0.0440149 0.00537834 0.0455" rpy="-1.5708 -0 -1.22173"/>
      <geometry>
        <mesh filename="package://assets/leg_plate.stl"/>
      </geometry>
      <material name="leg_plate_4_material">
        <color rgba="0.235294 0.235294 0.235294 1"/>
      </material>
    </visual>
    <collision>
      <origin xyz="0.0440149 0.00537834 0.0455" rpy="-1.5708 -0 -1.22173"/>
      <geometry>
        <mesh filename="package://assets/leg_plate.stl"/>
      </geometry>
    </collision>
    <!-- Part xl330_7 -->
    <visual>
      <origin xyz="-0.0394671 -0.0143648 -0.0145" rpy="2.79253 1.5708 0"/>
      <geometry>
        <mesh filename="package://assets/xl330.stl"/>
      </geometry>
      <material name="xl330_7_material">
        <color rgba="0.286275 0.286275 0.286275 1"/>
      </material>
    </visual>
    <collision>
      <origin xyz="-0.0394671 -0.0143648 -0.0145" rpy="2.79253 1.5708 0"/>
      <geometry>
        <mesh filename="package://assets/xl330.stl"/>
      </geometry>
    </collision>
  </link>
  <!-- Link foot -->
  <link name="foot">
    <inertial>
      <origin xyz="0.00475687 0.0144058 -0.0145" rpy="0 0 0"/>
      <mass value="0.01474"/>
      <inertia ixx="2.49961e-06" ixy="-7.3107e-08" ixz="-1.8e-11" iyy="5.27084e-06" iyz="-6e-12" izz="3.79703e-06"/>
    </inertial>
    <!-- Part foot -->
    <visual>
      <origin xyz="0.01 -0.1272 -0.0745" rpy="1.5708 -0 0"/>
      <geometry>
        <mesh filename="package://assets/foot.stl"/>
      </geometry>
      <material name="foot_material">
        <color rgba="1 0.756863 0.054902 1"/>
      </material>
    </visual>
    <collision>
      <origin xyz="0.01 -0.1272 -0.0745" rpy="1.5708 -0 0"/>
      <geometry>
        <mesh filename="package://assets/foot.stl"/>
      </geometry>
    </collision>
    <!-- Part foot_tpu_bottom -->
    <visual>
      <origin xyz="0.01 -0.1272 -0.0745" rpy="1.5708 -0 -0"/>
      <geometry>
        <mesh filename="package://assets/foot_tpu_bottom.stl"/>
      </geometry>
      <material name="foot_tpu_bottom_material">
        <color rgba="0.262745 0.262745 0.262745 1"/>
      </material>
    </visual>
    <collision>
      <origin xyz="0.01 -0.1272 -0.0745" rpy="1.5708 -0 -0"/>
      <geometry>
        <mesh filename="package://assets/foot_tpu_bottom.stl"/>
      </geometry>
    </collision>
  </link>
  <!-- Frame left_foot (dummy link + fixed joint) -->
  <link name="left_foot">
    <origin xyz="0 0 0" rpy="0 -0 0"/>
    <inertial>
      <origin xyz="0 0 0" rpy="0 0 0"/>
      <mass value="1e-9"/>
      <inertia ixx="0" ixy="0" ixz="0" iyy="0" iyz="0" izz="0"/>
    </inertial>
  </link>
  <joint name="left_foot_frame" type="fixed">
    <origin xyz="0.0048 0.021 -0.0145" rpy="1.5708 -0 -0"/>
    <parent link="foot"/>
    <child link="left_foot"/>
    <axis xyz="0 0 0"/>
  </joint>
  <!-- Joint from leg_plate_2 to foot -->
  <joint name="left_ankle" type="revolute">
    <origin xyz="-0.0394671 -0.0143648 -0" rpy="-0 0 2.53073"/>
    <parent link="leg_plate_2"/>
    <child link="foot"/>
    <axis xyz="0 0 1"/>
    <limit effort="10" velocity="10" lower="-2.18166" upper="0.959931"/>
  </joint>
  <!-- Joint from leg_plate to leg_plate_2 -->
  <joint name="left_knee" type="revolute">
    <origin xyz="-0.0344044 -0.0240902 -0" rpy="0 -0 -0.959931"/>
    <parent link="leg_plate"/>
    <child link="leg_plate_2"/>
    <axis xyz="0 0 1"/>
    <limit effort="10" velocity="10" lower="-0.698132" upper="1.22173"/>
  </joint>
  <!-- Joint from left_roll_to_pitch to leg_plate -->
  <joint name="left_hip_pitch" type="revolute">
    <origin xyz="0.0544 -0 -0.0245" rpy="1.5708 -0 1.5708"/>
    <parent link="left_roll_to_pitch"/>
    <child link="leg_plate"/>
    <axis xyz="0 0 1"/>
    <limit effort="10" velocity="10" lower="-0.610865" upper="0.959931"/>
  </joint>
  <!-- Joint from roll_motor_bottom to left_roll_to_pitch -->
  <joint name="left_hip_roll" type="revolute">
    <origin xyz="0 -0.01455 0.0286" rpy="-1.5708 -0 3.14159"/>
    <parent link="roll_motor_bottom"/>
    <child link="left_roll_to_pitch"/>
    <axis xyz="0 0 1"/>
    <limit effort="10" velocity="10" lower="-0.698132" upper="0.698132"/>
  </joint>
  <!-- Joint from trunk_base to roll_motor_bottom -->
  <joint name="left_hip_yaw" type="revolute">
    <origin xyz="0.0125202 0.02 0.0208" rpy="-3.14159 0 -1.5708"/>
    <parent link="trunk_base"/>
    <child link="roll_motor_bottom"/>
    <axis xyz="0 0 1"/>
    <limit effort="10" velocity="10" lower="-0.523599" upper="0.523599"/>
  </joint>
  <!-- Link long_neck_plate2 -->
  <link name="long_neck_plate2">
    <inertial>
      <origin xyz="0.0144963 0.0422391 -0.0147264" rpy="0 0 0"/>
      <mass value="0.02714"/>
      <inertia ixx="8.80674e-06" ixy="-2.28615e-06" ixz="1.8105e-08" iyy="4.73214e-06" iyz="3.4931e-08" izz="8.13706e-06"/>
    </inertial>
    <!-- Part long_neck_plate1 -->
    <visual>
      <origin xyz="0.0166519 -0.0273444 -0.0145" rpy="1.5708 0 2.79253"/>
      <geometry>
        <mesh filename="package://assets/long_neck_plate1.stl"/>
      </geometry>
      <material name="long_neck_plate1_material">
        <color rgba="0.235294 0.235294 0.235294 1"/>
      </material>
    </visual>
    <collision>
      <origin xyz="0.0166519 -0.0273444 -0.0145" rpy="1.5708 0 2.79253"/>
      <geometry>
        <mesh filename="package://assets/long_neck_plate1.stl"/>
      </geometry>
    </collision>
    <!-- Part neck_reinforcement -->
    <visual>
      <origin xyz="0.0166519 -0.0273444 -0.0145" rpy="1.5708 0 2.79253"/>
      <geometry>
        <mesh filename="package://assets/neck_reinforcement.stl"/>
      </geometry>
      <material name="neck_reinforcement_material">
        <color rgba="0.235294 0.235294 0.235294 1"/>
      </material>
    </visual>
    <collision>
      <origin xyz="0.0166519 -0.0273444 -0.0145" rpy="1.5708 0 2.79253"/>
      <geometry>
        <mesh filename="package://assets/neck_reinforcement.stl"/>
      </geometry>
    </collision>
    <!-- Part long_neck_plate2 -->
    <visual>
      <origin xyz="0.0166519 -0.0273444 -0.0145" rpy="1.5708 0 2.79253"/>
      <geometry>
        <mesh filename="package://assets/long_neck_plate2.stl"/>
      </geometry>
      <material name="long_neck_plate2_material">
        <color rgba="0.235294 0.235294 0.235294 1"/>
      </material>
    </visual>
    <collision>
      <origin xyz="0.0166519 -0.0273444 -0.0145" rpy="1.5708 0 2.79253"/>
      <geometry>
        <mesh filename="package://assets/long_neck_plate2.stl"/>
      </geometry>
    </collision>
    <!-- Part xl330_8 -->
    <visual>
      <origin xyz="0.0205212 0.0563816 -0.0145" rpy="-1.91986 -1.5708 0"/>
      <geometry>
        <mesh filename="package://assets/xl330.stl"/>
      </geometry>
      <material name="xl330_8_material">
        <color rgba="0.286275 0.286275 0.286275 1"/>
      </material>
    </visual>
    <collision>
      <origin xyz="0.0205212 0.0563816 -0.0145" rpy="-1.91986 -1.5708 0"/>
      <geometry>
        <mesh filename="package://assets/xl330.stl"/>
      </geometry>
    </collision>
  </link>
  <!-- Link head_pitch_to_yaw -->
  <link name="head_pitch_to_yaw">
    <inertial>
      <origin xyz="-0.0015591 0.0218351 -0.0145" rpy="0 0 0"/>
      <mass value="0.00677"/>
      <inertia ixx="2.43497e-06" ixy="1.02931e-07" ixz="-0" iyy="1.14024e-06" iyz="0" izz="2.0015e-06"/>
    </inertial>
    <!-- Part head_pitch_to_yaw -->
    <visual>
      <origin xyz="0.0508539 -0.0666249 -0.0145" rpy="1.5708 -0 -2.79253"/>
      <geometry>
        <mesh filename="package://assets/head_pitch_to_yaw.stl"/>
      </geometry>
      <material name="head_pitch_to_yaw_material">
        <color rgba="0.235294 0.235294 0.235294 1"/>
      </material>
    </visual>
    <collision>
      <origin xyz="0.0508539 -0.0666249 -0.0145" rpy="1.5708 -0 -2.79253"/>
      <geometry>
        <mesh filename="package://assets/head_pitch_to_yaw.stl"/>
      </geometry>
    </collision>
  </link>
  <!-- Link head_yaw_to_roll -->
  <link name="head_yaw_to_roll">
    <inertial>
      <origin xyz="0.00602348 0 0.0174917" rpy="0 0 0"/>
      <mass value="0.02914"/>
      <inertia ixx="4.9702e-06" ixy="0" ixz="6.69253e-07" iyy="1.03439e-05" iyz="0" izz="1.03996e-05"/>
    </inertial>
    <!-- Part head_yaw_to_roll -->
    <visual>
      <origin xyz="-0.025 0 0.1265" rpy="3.14159 -0 -0"/>
      <geometry>
        <mesh filename="package://assets/head_yaw_to_roll.stl"/>
      </geometry>
      <material name="head_yaw_to_roll_material">
        <color rgba="0.235294 0.235294 0.235294 1"/>
      </material>
    </visual>
    <collision>
      <origin xyz="-0.025 0 0.1265" rpy="3.14159 -0 -0"/>
      <geometry>
        <mesh filename="package://assets/head_yaw_to_roll.stl"/>
      </geometry>
    </collision>
    <!-- Part xl330_9 -->
    <visual>
      <origin xyz="-0 0 0.0145" rpy="3.14159 1.5708 0"/>
      <geometry>
        <mesh filename="package://assets/xl330.stl"/>
      </geometry>
      <material name="xl330_9_material">
        <color rgba="0.286275 0.286275 0.286275 1"/>
      </material>
    </visual>
    <collision>
      <origin xyz="-0 0 0.0145" rpy="3.14159 1.5708 0"/>
      <geometry>
        <mesh filename="package://assets/xl330.stl"/>
      </geometry>
    </collision>
  </link>
  <!-- Link head_base_plate -->
  <link name="head_base_plate">
    <inertial>
      <origin xyz="0.00140986 -0.00204907 -0.0254714" rpy="0 0 0"/>
      <mass value="0.11807"/>
      <inertia ixx="0.000259694" ixy="-1.74595e-07" ixz="-6.40852e-06" iyy="0.000285092" iyz="9.72161e-06" izz="7.12026e-05"/>
    </inertial>
    <!-- Part crossmember -->
    <visual>
      <origin xyz="-0 -0.112 -0.0556" rpy="-1.5708 -1.5708 0"/>
      <geometry>
        <mesh filename="package://assets/crossmember.stl"/>
      </geometry>
      <material name="crossmember_material">
        <color rgba="0.980392 0.713725 0.00392157 1"/>
      </material>
    </visual>
    <collision>
      <origin xyz="-0 -0.112 -0.0556" rpy="-1.5708 -1.5708 0"/>
      <geometry>
        <mesh filename="package://assets/crossmember.stl"/>
      </geometry>
    </collision>
    <!-- Part camshaft -->
    <visual>
      <origin xyz="-0 -0.112 -0.0556" rpy="-1.5708 -1.5708 0"/>
      <geometry>
        <mesh filename="package://assets/camshaft.stl"/>
      </geometry>
      <material name="camshaft_material">
        <color rgba="0.878431 0.223529 0.00392157 1"/>
      </material>
    </visual>
    <collision>
      <origin xyz="-0 -0.112 -0.0556" rpy="-1.5708 -1.5708 0"/>
      <geometry>
        <mesh filename="package://assets/camshaft.stl"/>
      </geometry>
    </collision>
    <!-- Part xl330_10 -->
    <visual>
      <origin xyz="0 0.009 -0.0791" rpy="1.5708 0 3.14159"/>
      <geometry>
        <mesh filename="package://assets/xl330.stl"/>
      </geometry>
      <material name="xl330_10_material">
        <color rgba="0.286275 0.286275 0.286275 1"/>
      </material>
    </visual>
    <collision>
      <origin xyz="0 0.009 -0.0791" rpy="1.5708 0 3.14159"/>
      <geometry>
        <mesh filename="package://assets/xl330.stl"/>
      </geometry>
    </collision>
    <!-- Part xl330_11 -->
    <visual>
      <origin xyz="-0 0 0.0145" rpy="-3.14159 1.5708 0"/>
      <geometry>
        <mesh filename="package://assets/xl330.stl"/>
      </geometry>
      <material name="xl330_11_material">
        <color rgba="0.286275 0.286275 0.286275 1"/>
      </material>
    </visual>
    <collision>
      <origin xyz="-0 0 0.0145" rpy="-3.14159 1.5708 0"/>
      <geometry>
        <mesh filename="package://assets/xl330.stl"/>
      </geometry>
    </collision>
    <!-- Part bearing_3 -->
    <visual>
      <origin xyz="-0.02 0 -0.1215" rpy="3.14159 0 1.5708"/>
      <geometry>
        <mesh filename="package://assets/bearing.stl"/>
      </geometry>
      <material name="bearing_3_material">
        <color rgba="0.701961 0.701961 0.701961 1"/>
      </material>
    </visual>
    <collision>
      <origin xyz="-0.02 0 -0.1215" rpy="3.14159 0 1.5708"/>
      <geometry>
        <mesh filename="package://assets/bearing.stl"/>
      </geometry>
    </collision>
    <!-- Part head_base_plate -->
    <visual>
      <origin xyz="-0 -0.112 -0.0556" rpy="-1.5708 -1.5708 0"/>
      <geometry>
        <mesh filename="package://assets/head_base_plate.stl"/>
      </geometry>
      <material name="head_base_plate_material">
        <color rgba="0.235294 0.235294 0.235294 1"/>
      </material>
    </visual>
    <collision>
      <origin xyz="-0 -0.112 -0.0556" rpy="-1.5708 -1.5708 0"/>
      <geometry>
        <mesh filename="package://assets/head_base_plate.stl"/>
      </geometry>
    </collision>
    <!-- Part mouth -->
    <visual>
      <origin xyz="-0 -0.112 -0.0556" rpy="-1.5708 -1.5708 0"/>
      <geometry>
        <mesh filename="package://assets/mouth.stl"/>
      </geometry>
      <material name="mouth_material">
        <color rgba="0.235294 0.235294 0.235294 1"/>
      </material>
    </visual>
    <collision>
      <origin xyz="-0 -0.112 -0.0556" rpy="-1.5708 -1.5708 0"/>
      <geometry>
        <mesh filename="package://assets/mouth.stl"/>
      </geometry>
    </collision>
    <!-- Part head_top -->
    <visual>
      <origin xyz="-0 -0.112 -0.0556" rpy="-1.5708 -1.5708 0"/>
      <geometry>
        <mesh filename="package://assets/head_top.stl"/>
      </geometry>
      <material name="head_top_material">
        <color rgba="0.6 0.6 0.6 1"/>
      </material>
    </visual>
    <collision>
      <origin xyz="-0 -0.112 -0.0556" rpy="-1.5708 -1.5708 0"/>
      <geometry>
        <mesh filename="package://assets/head_top.stl"/>
      </geometry>
    </collision>
  </link>
  <!-- Frame head_camera (dummy link + fixed joint) -->
  <link name="head_camera">
    <origin xyz="0 0 0" rpy="0 -0 0"/>
    <inertial>
      <origin xyz="0 0 0" rpy="0 0 0"/>
      <mass value="1e-9"/>
      <inertia ixx="0" ixy="0" ixz="0" iyy="0" iyz="0" izz="0"/>
    </inertial>
  </link>
  <joint name="head_camera_frame" type="fixed">
    <origin xyz="0 0.003 0.0394" rpy="-1.5708 -1.5708 0"/>
    <parent link="head_base_plate"/>
    <child link="head_camera"/>
    <axis xyz="0 0 0"/>
  </joint>
  <!-- Frame mouth_tip (dummy link + fixed joint) -->
  <link name="mouth_tip">
    <origin xyz="0 0 0" rpy="0 -0 0"/>
    <inertial>
      <origin xyz="0 0 0" rpy="0 0 0"/>
      <mass value="1e-9"/>
      <inertia ixx="0" ixy="0" ixz="0" iyy="0" iyz="0" izz="0"/>
    </inertial>
  </link>
  <joint name="mouth_tip_frame" type="fixed">
    <origin xyz="-0 -0.0175 0.0364" rpy="-1.5708 -1.5708 0"/>
    <parent link="head_base_plate"/>
    <child link="mouth_tip"/>
    <axis xyz="0 0 0"/>
  </joint>
  <!-- Joint from head_yaw_to_roll to head_base_plate -->
  <joint name="head_roll" type="revolute">
    <origin xyz="0.0305 0 0.0145" rpy="-1.5708 -0 -1.5708"/>
    <parent link="head_yaw_to_roll"/>
    <child link="head_base_plate"/>
    <axis xyz="0 0 1"/>
    <limit effort="10" velocity="10" lower="-0.523599" upper="0.523599"/>
  </joint>
  <!-- Joint from head_pitch_to_yaw to head_yaw_to_roll -->
  <joint name="head_yaw" type="revolute">
    <origin xyz="-0.0159039 0.0436957 -0.0145" rpy="-1.5708 -0 -2.79253"/>
    <parent link="head_pitch_to_yaw"/>
    <child link="head_yaw_to_roll"/>
    <axis xyz="0 0 1"/>
    <limit effort="10" velocity="10" lower="-2.61799" upper="2.61799"/>
  </joint>
  <!-- Joint from long_neck_plate2 to head_pitch_to_yaw -->
  <joint name="head_pitch" type="revolute">
    <origin xyz="0.0205212 0.0563816 -0" rpy="-0 -0 -0.349066"/>
    <parent link="long_neck_plate2"/>
    <child link="head_pitch_to_yaw"/>
    <axis xyz="0 0 1"/>
    <limit effort="10" velocity="10" lower="-1.5708" upper="0.872665"/>
  </joint>
  <!-- Joint from trunk_base to long_neck_plate2 -->
  <joint name="neck_pitch" type="revolute">
    <origin xyz="0.0375202 0.0146 0.0552" rpy="1.5708 -0 -3.14159"/>
    <parent link="trunk_base"/>
    <child link="long_neck_plate2"/>
    <axis xyz="0 0 1"/>
    <limit effort="10" velocity="10" lower="-0.872665" upper="2.44346"/>
  </joint>
  <!-- Link xl330 -->
  <link name="xl330">
    <inertial>
      <origin xyz="0.000243808 0 0.0205921" rpy="0 0 0"/>
      <mass value="0.0250187"/>
      <inertia ixx="5.01807e-06" ixy="-0" ixz="1.8994e-08" iyy="5.56855e-06" iyz="-0" izz="2.44472e-06"/>
    </inertial>
    <!-- Part roll_motor_top_2 -->
    <visual>
      <origin xyz="0 0.02 -0.0146" rpy="3.14159 0 -0"/>
      <geometry>
        <mesh filename="package://assets/roll_motor_top.stl"/>
      </geometry>
      <material name="roll_motor_top_2_material">
        <color rgba="0.235294 0.235294 0.235294 1"/>
      </material>
    </visual>
    <collision>
      <origin xyz="0 0.02 -0.0146" rpy="3.14159 0 -0"/>
      <geometry>
        <mesh filename="package://assets/roll_motor_top.stl"/>
      </geometry>
    </collision>
    <!-- Part roll_motor_bottom_2 -->
    <visual>
      <origin xyz="5e-05 0.02 -0.0146" rpy="3.14159 0 -0"/>
      <geometry>
        <mesh filename="package://assets/roll_motor_bottom.stl"/>
      </geometry>
      <material name="roll_motor_bottom_2_material">
        <color rgba="0.235294 0.235294 0.235294 1"/>
      </material>
    </visual>
    <collision>
      <origin xyz="5e-05 0.02 -0.0146" rpy="3.14159 0 -0"/>
      <geometry>
        <mesh filename="package://assets/roll_motor_bottom.stl"/>
      </geometry>
    </collision>
    <!-- Part xl330_12 -->
    <visual>
      <origin xyz="5e-05 0 0.0286" rpy="0 -0 3.14159"/>
      <geometry>
        <mesh filename="package://assets/xl330.stl"/>
      </geometry>
      <material name="xl330_12_material">
        <color rgba="0.286275 0.286275 0.286275 1"/>
      </material>
    </visual>
    <collision>
      <origin xyz="5e-05 0 0.0286" rpy="0 -0 3.14159"/>
      <geometry>
        <mesh filename="package://assets/xl330.stl"/>
      </geometry>
    </collision>
  </link>
  <!-- Link right_roll_to_pitch -->
  <link name="right_roll_to_pitch">
    <inertial>
      <origin xyz="-0.0359029 0.00016252 -0.0142127" rpy="0 0 0"/>
      <mass value="0.02709"/>
      <inertia ixx="4.61259e-06" ixy="-7.4483e-08" ixz="-4.8292e-08" iyy="7.88911e-06" iyz="1.1887e-08" izz="5.4019e-06"/>
    </inertial>
    <!-- Part right_roll_to_pitch -->
    <visual>
      <origin xyz="0.02 0.0432 -0.0145" rpy="-1.5708 -1.5708 0"/>
      <geometry>
        <mesh filename="package://assets/right_roll_to_pitch.stl"/>
      </geometry>
      <material name="right_roll_to_pitch_material">
        <color rgba="0.235294 0.235294 0.235294 1"/>
      </material>
    </visual>
    <collision>
      <origin xyz="0.02 0.0432 -0.0145" rpy="-1.5708 -1.5708 0"/>
      <geometry>
        <mesh filename="package://assets/right_roll_to_pitch.stl"/>
      </geometry>
    </collision>
    <!-- Part xl330_13 -->
    <visual>
      <origin xyz="-0.0399 0 -0.0245" rpy="3.14159 0 0"/>
      <geometry>
        <mesh filename="package://assets/xl330.stl"/>
      </geometry>
      <material name="xl330_13_material">
        <color rgba="0.286275 0.286275 0.286275 1"/>
      </material>
    </visual>
    <collision>
      <origin xyz="-0.0399 0 -0.0245" rpy="3.14159 0 0"/>
      <geometry>
        <mesh filename="package://assets/xl330.stl"/>
      </geometry>
    </collision>
  </link>
  <!-- Link xl330_2 -->
  <link name="xl330_2">
    <inertial>
      <origin xyz="0.0249844 -0.0174942 -0.0142358" rpy="0 0 0"/>
      <mass value="0.02326"/>
      <inertia ixx="3.99665e-06" ixy="1.39876e-06" ixz="-1.2581e-08" iyy="5.01487e-06" iyz="8.809e-09" izz="4.77213e-06"/>
    </inertial>
    <!-- Part xl330_14 -->
    <visual>
      <origin xyz="0.0344044 -0.0240902 -0.0145" rpy="0.610865 1.5708 0"/>
      <geometry>
        <mesh filename="package://assets/xl330.stl"/>
      </geometry>
      <material name="xl330_14_material">
        <color rgba="0.286275 0.286275 0.286275 1"/>
      </material>
    </visual>
    <collision>
      <origin xyz="0.0344044 -0.0240902 -0.0145" rpy="0.610865 1.5708 0"/>
      <geometry>
        <mesh filename="package://assets/xl330.stl"/>
      </geometry>
    </collision>
    <!-- Part leg_plate_5 -->
    <visual>
      <origin xyz="-0.0296516 0.03297 0.0455" rpy="-1.5708 -0 0.959931"/>
      <geometry>
        <mesh filename="package://assets/leg_plate.stl"/>
      </geometry>
      <material name="leg_plate_5_material">
        <color rgba="0.235294 0.235294 0.235294 1"/>
      </material>
    </visual>
    <collision>
      <origin xyz="-0.0296516 0.03297 0.0455" rpy="-1.5708 -0 0.959931"/>
      <geometry>
        <mesh filename="package://assets/leg_plate.stl"/>
      </geometry>
    </collision>
    <!-- Part leg_plate_6 -->
    <visual>
      <origin xyz="-0.0411231 0.016587 -0.0745" rpy="1.5708 -0 -2.18166"/>
      <geometry>
        <mesh filename="package://assets/leg_plate.stl"/>
      </geometry>
      <material name="leg_plate_6_material">
        <color rgba="0.235294 0.235294 0.235294 1"/>
      </material>
    </visual>
    <collision>
      <origin xyz="-0.0411231 0.016587 -0.0745" rpy="1.5708 -0 -2.18166"/>
      <geometry>
        <mesh filename="package://assets/leg_plate.stl"/>
      </geometry>
    </collision>
  </link>
  <!-- Link xl330_3 -->
  <link name="xl330_3">
    <inertial>
      <origin xyz="0.0286609 -0.0104317 -0.0142358" rpy="0 0 0"/>
      <mass value="0.02326"/>
      <inertia ixx="3.36548e-06" ixy="9.56811e-07" ixz="-1.4432e-08" iyy="5.64605e-06" iyz="5.253e-09" izz="4.77213e-06"/>
    </inertial>
    <!-- Part xl330_15 -->
    <visual>
      <origin xyz="0.0394671 -0.0143648 -0.0145" rpy="0.349066 1.5708 0"/>
      <geometry>
        <mesh filename="package://assets/xl330.stl"/>
      </geometry>
      <material name="xl330_15_material">
        <color rgba="0.286275 0.286275 0.286275 1"/>
      </material>
    </visual>
    <collision>
      <origin xyz="0.0394671 -0.0143648 -0.0145" rpy="0.349066 1.5708 0"/>
      <geometry>
        <mesh filename="package://assets/xl330.stl"/>
      </geometry>
    </collision>
    <!-- Part leg_plate_7 -->
    <visual>
      <origin xyz="-0.0371745 0.0241722 0.0455" rpy="-1.5708 0 1.22173"/>
      <geometry>
        <mesh filename="package://assets/leg_plate.stl"/>
      </geometry>
      <material name="leg_plate_7_material">
        <color rgba="0.235294 0.235294 0.235294 1"/>
      </material>
    </visual>
    <collision>
      <origin xyz="-0.0371745 0.0241722 0.0455" rpy="-1.5708 0 1.22173"/>
      <geometry>
        <mesh filename="package://assets/leg_plate.stl"/>
      </geometry>
    </collision>
    <!-- Part leg_plate_8 -->
    <visual>
      <origin xyz="-0.0440149 0.00537834 -0.0745" rpy="1.5708 -0 -1.91986"/>
      <geometry>
        <mesh filename="package://assets/leg_plate.stl"/>
      </geometry>
      <material name="leg_plate_8_material">
        <color rgba="0.235294 0.235294 0.235294 1"/>
      </material>
    </visual>
    <collision>
      <origin xyz="-0.0440149 0.00537834 -0.0745" rpy="1.5708 -0 -1.91986"/>
      <geometry>
        <mesh filename="package://assets/leg_plate.stl"/>
      </geometry>
    </collision>
  </link>
  <!-- Link foot_2 -->
  <link name="foot_2">
    <inertial>
      <origin xyz="0.00475687 -0.0144058 -0.0145" rpy="0 0 0"/>
      <mass value="0.01474"/>
      <inertia ixx="2.49961e-06" ixy="7.3107e-08" ixz="1.8e-11" iyy="5.27084e-06" iyz="-6e-12" izz="3.79703e-06"/>
    </inertial>
    <!-- Part foot_tpu_bottom_2 -->
    <visual>
      <origin xyz="0.01 0.1272 0.0455" rpy="-1.5708 -0 0"/>
      <geometry>
        <mesh filename="package://assets/foot_tpu_bottom.stl"/>
      </geometry>
      <material name="foot_tpu_bottom_2_material">
        <color rgba="0.262745 0.262745 0.262745 1"/>
      </material>
    </visual>
    <collision>
      <origin xyz="0.01 0.1272 0.0455" rpy="-1.5708 -0 0"/>
      <geometry>
        <mesh filename="package://assets/foot_tpu_bottom.stl"/>
      </geometry>
    </collision>
    <!-- Part foot_2 -->
    <visual>
      <origin xyz="0.01 0.1272 0.0455" rpy="-1.5708 0 0"/>
      <geometry>
        <mesh filename="package://assets/foot.stl"/>
      </geometry>
      <material name="foot_2_material">
        <color rgba="1 0.756863 0.054902 1"/>
      </material>
    </visual>
    <collision>
      <origin xyz="0.01 0.1272 0.0455" rpy="-1.5708 0 0"/>
      <geometry>
        <mesh filename="package://assets/foot.stl"/>
      </geometry>
    </collision>
  </link>
  <!-- Frame right_foot (dummy link + fixed joint) -->
  <link name="right_foot">
    <origin xyz="0 0 0" rpy="0 -0 0"/>
    <inertial>
      <origin xyz="0 0 0" rpy="0 0 0"/>
      <mass value="1e-9"/>
      <inertia ixx="0" ixy="0" ixz="0" iyy="0" iyz="0" izz="0"/>
    </inertial>
  </link>
  <joint name="right_foot_frame" type="fixed">
    <origin xyz="0.0048 -0.021 -0.0145" rpy="-1.5708 -0 0"/>
    <parent link="foot_2"/>
    <child link="right_foot"/>
    <axis xyz="0 0 0"/>
  </joint>
  <!-- Joint from xl330_3 to foot_2 -->
  <joint name="right_ankle" type="revolute">
    <origin xyz="0.0394671 -0.0143648 -0" rpy="0 0 0.610865"/>
    <parent link="xl330_3"/>
    <child link="foot_2"/>
    <axis xyz="0 0 1"/>
    <limit effort="10" velocity="10" lower="-0.959931" upper="2.18166"/>
  </joint>
  <!-- Joint from xl330_2 to xl330_3 -->
  <joint name="right_knee" type="revolute">
    <origin xyz="0.0344044 -0.0240902 -0" rpy="0 -0 0.959931"/>
    <parent link="xl330_2"/>
    <child link="xl330_3"/>
    <axis xyz="0 0 1"/>
    <limit effort="10" velocity="10" lower="-1.22173" upper="0.698132"/>
  </joint>
  <!-- Joint from right_roll_to_pitch to xl330_2 -->
  <joint name="right_hip_pitch" type="revolute">
    <origin xyz="-0.0544 0 -0.0245" rpy="1.5708 -0 -1.5708"/>
    <parent link="right_roll_to_pitch"/>
    <child link="xl330_2"/>
    <axis xyz="0 0 1"/>
    <limit effort="10" velocity="10" lower="-0.959931" upper="0.610865"/>
  </joint>
  <!-- Joint from xl330 to right_roll_to_pitch -->
  <joint name="right_hip_roll" type="revolute">
    <origin xyz="0.01455 0 0.0286" rpy="-1.5708 -0 -1.5708"/>
    <parent link="xl330"/>
    <child link="right_roll_to_pitch"/>
    <axis xyz="0 0 1"/>
    <limit effort="10" velocity="10" lower="-0.698132" upper="0.698132"/>
  </joint>
  <!-- Joint from trunk_base to xl330 -->
  <joint name="right_hip_yaw" type="revolute">
    <origin xyz="0.0125202 -0.02 0.0208" rpy="-3.14159 -0 -0"/>
    <parent link="trunk_base"/>
    <child link="xl330"/>
    <axis xyz="0 0 1"/>
    <limit effort="10" velocity="10" lower="-0.523599" upper="0.523599"/>
  </joint>
</robot>
